<?xml version="1.0"?>
<robot xmlns:xacro="http://www.ros.org/wiki/xacro">

    <xacro:include filename="robot.material.xacro" />
    <xacro:include filename="inertial_macros.xacro" />

    <!-- BASE LINK -->
    <link name="base_link"></link>


    <!-- BASE_PLATE LINK -->
    <joint name="base_plate_joint" type="fixed">
        <parent link="base_link" />
        <child link="base_plate" />
        <origin xyz="-0.12825 0 -0.0435" />
    </joint>

    <link name="base_plate">
        <visual>
            <origin xyz="0.096 0 0.0025" />
            <geometry>
                <box size="0.192 0.164 0.005" />
            </geometry>
            <material name="black" />
        </visual>
        <collision>
            <origin xyz="0.096 0 0.0025" />
            <geometry>
                <box size="0.192 0.164 0.005" />
            </geometry>
        </collision>
        <xacro:inertial_box mass="0.5" x="0.192" y="0.164" z="0.005">
            <origin xyz="0.096 0 0.0025" rpy="0 0 0"/>
        </xacro:inertial_box>
    </link>

    <!-- LEFT_WHEEL LINK -->
    <joint name="left_wheel_joint" type="continuous">
        <parent link="base_link" />
        <child link="left_wheel" />
        <origin xyz="0 0.092 0" rpy="-${pi/2} 0 0" />
        <axis xyz="0 0 1" />
    </joint>

    <link name="left_wheel">
        <visual>
            <origin xyz="0 0 0" />
            <geometry>
                <cylinder radius="0.06" length="0.01" />
            </geometry>
            <material name="grey" />
        </visual>
        <collision>
            <origin xyz="0 0 0" />
            <geometry>
                <cylinder radius="0.06" length="0.001" />
            </geometry>
        </collision>
        <xacro:inertial_cylinder mass="0.1" length="0.01" radius="0.06">
            <origin xyz="0 0 0" rpy="0 0 0"/>
        </xacro:inertial_cylinder>
    </link>

    <!-- RIGHT_WHEEL LINK -->
    <joint name="right_wheel_joint" type="continuous">
        <parent link="base_link" />
        <child link="right_wheel" />
        <origin xyz="0 -0.092 0" rpy="${pi/2} 0 0" />
        <axis xyz="0 0 -1" />
    </joint>

    <link name="right_wheel">
        <visual>
            <origin xyz="0 0 0" />
            <geometry>
                <cylinder radius="0.06" length="0.01" />
            </geometry>
            <material name="grey" />
        </visual>
        <collision>
            <origin xyz="0 0 0" />
            <geometry>
                <cylinder radius="0.06" length="0.001" />
            </geometry>
        </collision>
        <xacro:inertial_cylinder mass="0.1" length="0.01" radius="0.06">
            <origin xyz="0 0 0" rpy="0 0 0"/>
        </xacro:inertial_cylinder>
    </link>

    <!-- CASTER_WHEEL LINK -->
    <joint name="caster_wheel_joint" type="fixed">
        <parent link="base_link" />
        <child link="caster_wheel" />
        <origin xyz="-0.10325 0 -0.035" />
    </joint>


    <link name="caster_wheel">
        <visual>
            <origin xyz="0 0 0" />
            <geometry>
                <sphere radius="0.025" />
            </geometry>
            <material name="green" />
        </visual>
        <collision>
            <origin xyz="0 0 0" />
            <geometry>
                <sphere radius="0.025" />
            </geometry>
        </collision>
        <xacro:inertial_sphere mass="0.1" radius="0.025">
            <origin xyz="0 0 0" rpy="0 0 0"/>
        </xacro:inertial_sphere>
    </link>
</robot>